2024-10-14 22:54:35 - ExceptionLogger - ERROR - An exception occurred
Traceback (most recent call last):
  File "C:\Users\shaik\AppData\Local\Temp\ipykernel_33508\3678882227.py", line 39, in log_exception
    result = 10 / 0
             ~~~^~~
ZeroDivisionError: division by zero
